<?xml version="1.0" encoding="utf-8"?>
<!-- This URDF was automatically created by SolidWorks to URDF Exporter! Originally created by Stephen Brawner (brawner@gmail.com) 
     Commit Version: 1.5.1-0-g916b5db  Build Version: 1.5.7152.31018
     For more information, please see http://wiki.ros.org/sw_urdf_exporter -->
<robot
  name="smr100e_description">
  <link
    name="base_link">
    <inertial>
      <origin
        xyz="0.010919 -0.00079912 0.23958"
        rpy="0 0 0" />
      <mass
        value="17.77" />
      <inertia
        ixx="0.64255"
        ixy="-0.002326"
        ixz="0.047666"
        iyy="1.531"
        iyz="-0.0011678"
        izz="1.626" />
    </inertial>
    <visual>
      <origin
        xyz="0 0 0"
        rpy="0 0 0" />
      <geometry>
        <mesh
          filename="package://smr100e_description/meshes/base_link.STL" />
      </geometry>
      <material
        name="">
        <color
          rgba="0.79216 0.81961 0.93333 1" />
      </material>
    </visual>
    <collision>
      <origin
        xyz="0 0 0"
        rpy="0 0 0" />
      <geometry>
        <mesh
          filename="package://smr100e_description/meshes/base_link.STL" />
      </geometry>
    </collision>
  </link>
  <link
    name="wheel_left_link">
    <inertial>
      <origin
        xyz="5.7207E-08 3.3262E-05 -9.2679E-05"
        rpy="0 0 0" />
      <mass
        value="4.9554" />
      <inertia
        ixx="0.0087272"
        ixy="-4.3289E-09"
        ixz="-2.7053E-08"
        iyy="0.01571"
        iyz="2.8551E-06"
        izz="0.0087185" />
    </inertial>
    <visual>
      <origin
        xyz="0 0 0"
        rpy="0 0 0" />
      <geometry>
        <mesh
          filename="package://smr100e_description/meshes/wheel_left_link.STL" />
      </geometry>
      <material
        name="">
        <color
          rgba="0.79216 0.79216 0.79216 1" />
      </material>
    </visual>
    <collision>
      <origin
        xyz="0 0 0"
        rpy="0 0 0" />
      <geometry>
        <mesh
          filename="package://smr100e_description/meshes/wheel_left_link.STL" />
      </geometry>
    </collision>
  </link>
  <joint
    name="wheel_left_joint"
    type="continuous">
    <origin
      xyz="0 0.184 0.075"
      rpy="0 0 0" />
    <parent
      link="base_link" />
    <child
      link="wheel_left_link" />
    <axis
      xyz="0 -1 0" />
  </joint>
  <link
    name="caster_front_left_arm_link">
    <inertial>
      <origin
        xyz="-0.0084392 6.8287E-05 -0.022004"
        rpy="0 0 0" />
      <mass
        value="0.11922" />
      <inertia
        ixx="0.00011949"
        ixy="2.5918E-07"
        ixz="-3.3659E-05"
        iyy="0.00013144"
        iyz="3.8695E-07"
        izz="0.0001377" />
    </inertial>
    <visual>
      <origin
        xyz="0 0 0"
        rpy="0 0 0" />
      <geometry>
        <mesh
          filename="package://smr100e_description/meshes/caster_front_left_arm_link.STL" />
      </geometry>
      <material
        name="">
        <color
          rgba="0.79216 0.81961 0.93333 1" />
      </material>
    </visual>
    <collision>
      <origin
        xyz="0 0 0"
        rpy="0 0 0" />
      <geometry>
        <mesh
          filename="package://smr100e_description/meshes/caster_front_left_arm_link.STL" />
      </geometry>
    </collision>
  </link>
  <joint
    name="caster_front_left_arm_joint"
    type="continuous">
    <origin
      xyz="0.3725 0.155 0.10942"
      rpy="0 0 0" />
    <parent
      link="base_link" />
    <child
      link="caster_front_left_arm_link" />
    <axis
      xyz="0 0 1" />
  </joint>
  <link
    name="caster_front_left_wheel_link">
    <inertial>
      <origin
        xyz="9.0636E-06 1.0025E-05 -3.4158E-05"
        rpy="0 0 0" />
      <mass
        value="0.10623" />
      <inertia
        ixx="5.3145E-05"
        ixy="-1.3094E-08"
        ixz="-1.6364E-09"
        iyy="9.0791E-05"
        iyz="1.1955E-08"
        izz="5.3158E-05" />
    </inertial>
    <visual>
      <origin
        xyz="0 0 0"
        rpy="0 0 0" />
      <geometry>
        <mesh
          filename="package://smr100e_description/meshes/caster_front_left_wheel_link.STL" />
      </geometry>
      <material
        name="">
        <color
          rgba="0.79216 0.81961 0.93333 1" />
      </material>
    </visual>
    <collision>
      <origin
        xyz="0 0 0"
        rpy="0 0 0" />
      <geometry>
        <mesh
          filename="package://smr100e_description/meshes/caster_front_left_wheel_link.STL" />
      </geometry>
    </collision>
  </link>
  <joint
    name="caster_front_left_wheel_joint"
    type="continuous">
    <origin
      xyz="-0.04 -0.0005 -0.07"
      rpy="0 0 0" />
    <parent
      link="caster_front_left_arm_link" />
    <child
      link="caster_front_left_wheel_link" />
    <axis
      xyz="0 -1 0" />
  </joint>
  <link
    name="caster_rear_left_arm_link">
    <inertial>
      <origin
        xyz="-0.0084392 6.8287E-05 -0.022004"
        rpy="0 0 0" />
      <mass
        value="0.11922" />
      <inertia
        ixx="0.00011949"
        ixy="2.5918E-07"
        ixz="-3.3659E-05"
        iyy="0.00013144"
        iyz="3.8695E-07"
        izz="0.0001377" />
    </inertial>
    <visual>
      <origin
        xyz="0 0 0"
        rpy="0 0 0" />
      <geometry>
        <mesh
          filename="package://smr100e_description/meshes/caster_rear_left_arm_link.STL" />
      </geometry>
      <material
        name="">
        <color
          rgba="0.79216 0.81961 0.93333 1" />
      </material>
    </visual>
    <collision>
      <origin
        xyz="0 0 0"
        rpy="0 0 0" />
      <geometry>
        <mesh
          filename="package://smr100e_description/meshes/caster_rear_left_arm_link.STL" />
      </geometry>
    </collision>
  </link>
  <joint
    name="caster_rear_left_arm_joint"
    type="continuous">
    <origin
      xyz="-0.3725 0.155 0.10942"
      rpy="0 0 0" />
    <parent
      link="base_link" />
    <child
      link="caster_rear_left_arm_link" />
    <axis
      xyz="0 0 1" />
  </joint>
  <link
    name="caster_rear_left_wheel_link">
    <inertial>
      <origin
        xyz="9.0636E-06 1.0025E-05 -3.4158E-05"
        rpy="0 0 0" />
      <mass
        value="0.10623" />
      <inertia
        ixx="5.3145E-05"
        ixy="-1.3094E-08"
        ixz="-1.6364E-09"
        iyy="9.0791E-05"
        iyz="1.1955E-08"
        izz="5.3158E-05" />
    </inertial>
    <visual>
      <origin
        xyz="0 0 0"
        rpy="0 0 0" />
      <geometry>
        <mesh
          filename="package://smr100e_description/meshes/caster_rear_left_wheel_link.STL" />
      </geometry>
      <material
        name="">
        <color
          rgba="0.79216 0.81961 0.93333 1" />
      </material>
    </visual>
    <collision>
      <origin
        xyz="0 0 0"
        rpy="0 0 0" />
      <geometry>
        <mesh
          filename="package://smr100e_description/meshes/caster_rear_left_wheel_link.STL" />
      </geometry>
    </collision>
  </link>
  <joint
    name="caster_rear_left_wheel_joint"
    type="continuous">
    <origin
      xyz="-0.04 -0.0002 -0.07"
      rpy="0 0 0" />
    <parent
      link="caster_rear_left_arm_link" />
    <child
      link="caster_rear_left_wheel_link" />
    <axis
      xyz="0 -1 0" />
  </joint>
  <link
    name="wheel_right_link">
    <inertial>
      <origin
        xyz="-5.7206E-08 -3.3262E-05 -9.2679E-05"
        rpy="0 0 0" />
      <mass
        value="4.9554" />
      <inertia
        ixx="0.0087272"
        ixy="-4.3288E-09"
        ixz="2.7053E-08"
        iyy="0.01571"
        iyz="-2.8551E-06"
        izz="0.0087185" />
    </inertial>
    <visual>
      <origin
        xyz="0 0 0"
        rpy="0 0 0" />
      <geometry>
        <mesh
          filename="package://smr100e_description/meshes/wheel_right_link.STL" />
      </geometry>
      <material
        name="">
        <color
          rgba="0.79216 0.79216 0.79216 1" />
      </material>
    </visual>
    <collision>
      <origin
        xyz="0 0 0"
        rpy="0 0 0" />
      <geometry>
        <mesh
          filename="package://smr100e_description/meshes/wheel_right_link.STL" />
      </geometry>
    </collision>
  </link>
  <joint
    name="wheel_right_joint"
    type="continuous">
    <origin
      xyz="0 -0.184 0.075"
      rpy="0 0 0" />
    <parent
      link="base_link" />
    <child
      link="wheel_right_link" />
    <axis
      xyz="0 1 0" />
  </joint>
  <link
    name="caster_front_right_arm_link">
    <inertial>
      <origin
        xyz="-0.0084392 6.8287E-05 -0.022004"
        rpy="0 0 0" />
      <mass
        value="0.11922" />
      <inertia
        ixx="0.00011949"
        ixy="2.5918E-07"
        ixz="-3.3659E-05"
        iyy="0.00013144"
        iyz="3.8695E-07"
        izz="0.0001377" />
    </inertial>
    <visual>
      <origin
        xyz="0 0 0"
        rpy="0 0 0" />
      <geometry>
        <mesh
          filename="package://smr100e_description/meshes/caster_front_right_arm_link.STL" />
      </geometry>
      <material
        name="">
        <color
          rgba="0.79216 0.81961 0.93333 1" />
      </material>
    </visual>
    <collision>
      <origin
        xyz="0 0 0"
        rpy="0 0 0" />
      <geometry>
        <mesh
          filename="package://smr100e_description/meshes/caster_front_right_arm_link.STL" />
      </geometry>
    </collision>
  </link>
  <joint
    name="cater_front_right_arm_joint"
    type="continuous">
    <origin
      xyz="0.3725 -0.155 0.10942"
      rpy="0 0 0" />
    <parent
      link="base_link" />
    <child
      link="caster_front_right_arm_link" />
    <axis
      xyz="0 0 1" />
  </joint>
  <link
    name="caster_front_right_wheel_link">
    <inertial>
      <origin
        xyz="9.0636E-06 1.0025E-05 -3.4158E-05"
        rpy="0 0 0" />
      <mass
        value="0.10623" />
      <inertia
        ixx="5.3145E-05"
        ixy="-1.3094E-08"
        ixz="-1.6364E-09"
        iyy="9.0791E-05"
        iyz="1.1955E-08"
        izz="5.3158E-05" />
    </inertial>
    <visual>
      <origin
        xyz="0 0 0"
        rpy="0 0 0" />
      <geometry>
        <mesh
          filename="package://smr100e_description/meshes/caster_front_right_wheel_link.STL" />
      </geometry>
      <material
        name="">
        <color
          rgba="0.79216 0.81961 0.93333 1" />
      </material>
    </visual>
    <collision>
      <origin
        xyz="0 0 0"
        rpy="0 0 0" />
      <geometry>
        <mesh
          filename="package://smr100e_description/meshes/caster_front_right_wheel_link.STL" />
      </geometry>
    </collision>
  </link>
  <joint
    name="caster_front_right_wheel_joint"
    type="continuous">
    <origin
      xyz="-0.04 -0.0002 -0.07"
      rpy="0 0 0" />
    <parent
      link="caster_front_right_arm_link" />
    <child
      link="caster_front_right_wheel_link" />
    <axis
      xyz="0 1 0" />
  </joint>
  <link
    name="caster_rear_right_arm_link">
    <inertial>
      <origin
        xyz="-0.00843923711974914 6.82869071934045E-05 -0.0220040709728501"
        rpy="0 0 0" />
      <mass
        value="0.11922001614021" />
      <inertia
        ixx="0.000119486348254277"
        ixy="2.59184030283027E-07"
        ixz="-3.36592440878E-05"
        iyy="0.000131444230633922"
        iyz="3.86949272720468E-07"
        izz="0.000137700254543915" />
    </inertial>
    <visual>
      <origin
        xyz="0 0 0"
        rpy="0 0 0" />
      <geometry>
        <mesh
          filename="package://smr100e_description/meshes/caster_rear_right_arm_link.STL" />
      </geometry>
      <material
        name="">
        <color
          rgba="0.792156862745098 0.819607843137255 0.933333333333333 1" />
      </material>
    </visual>
    <collision>
      <origin
        xyz="0 0 0"
        rpy="0 0 0" />
      <geometry>
        <mesh
          filename="package://smr100e_description/meshes/caster_rear_right_arm_link.STL" />
      </geometry>
    </collision>
  </link>
  <joint
    name="caster_rear_right_arm_joint"
    type="continuous">
    <origin
      xyz="-0.3725 -0.155 0.10942"
      rpy="0 0 0" />
    <parent
      link="base_link" />
    <child
      link="caster_rear_right_arm_link" />
    <axis
      xyz="0 0 1" />
  </joint>
  <link
    name="caster_rear_right_wheel_link">
    <inertial>
      <origin
        xyz="9.0635610097145E-06 1.00246685700023E-05 -3.41579619149227E-05"
        rpy="0 0 0" />
      <mass
        value="0.106227739121479" />
      <inertia
        ixx="5.31454154966382E-05"
        ixy="-1.30943250317608E-08"
        ixz="-1.63641579326325E-09"
        iyy="9.07905500875471E-05"
        iyz="1.19552325589121E-08"
        izz="5.31582091921388E-05" />
    </inertial>
    <visual>
      <origin
        xyz="0 0 0"
        rpy="0 0 0" />
      <geometry>
        <mesh
          filename="package://smr100e_description/meshes/caster_rear_right_wheel_link.STL" />
      </geometry>
      <material
        name="">
        <color
          rgba="0.792156862745098 0.819607843137255 0.933333333333333 1" />
      </material>
    </visual>
    <collision>
      <origin
        xyz="0 0 0"
        rpy="0 0 0" />
      <geometry>
        <mesh
          filename="package://smr100e_description/meshes/caster_rear_right_wheel_link.STL" />
      </geometry>
    </collision>
  </link>
  <joint
    name="caster_rear_right_wheel_joint"
    type="continuous">
    <origin
      xyz="-0.04 -0.0005 -0.07"
      rpy="0 0 0" />
    <parent
      link="caster_rear_right_arm_link" />
    <child
      link="caster_rear_right_wheel_link" />
    <axis
      xyz="0 1 0" />
  </joint>
  <link
    name="lidar_link">
    <inertial>
      <origin
        xyz="-0.00233498101477952 -1.38294948264555E-06 -0.0129543211135779"
        rpy="0 0 0" />
      <mass
        value="0.0967444163686206" />
      <inertia
        ixx="6.75053726572271E-05"
        ixy="-4.85104312872503E-08"
        ixz="-2.38171290588733E-06"
        iyy="8.2230288975979E-05"
        iyz="-1.88559772177136E-08"
        izz="0.000116331696785306" />
    </inertial>
    <visual>
      <origin
        xyz="0 0 0"
        rpy="0 0 0" />
      <geometry>
        <mesh
          filename="package://smr100e_description/meshes/lidar_link.STL" />
      </geometry>
      <material
        name="">
        <color
          rgba="0.898039215686275 0.917647058823529 0.929411764705882 1" />
      </material>
    </visual>
    <collision>
      <origin
        xyz="0 0 0"
        rpy="0 0 0" />
      <geometry>
        <mesh
          filename="package://smr100e_description/meshes/lidar_link.STL" />
      </geometry>
    </collision>
  </link>
  <joint
    name="lidar_joint"
    type="fixed">
    <origin
      xyz="0.4425 0 0.15992"
      rpy="0 0 0" />
    <parent
      link="base_link" />
    <child
      link="lidar_link" />
    <axis
      xyz="0 0 0" />
  </joint>
  <link
    name="imu_link">
    <inertial>
      <origin
        xyz="-6.93505865297182E-05 2.10656642645746E-05 -0.001722725779644"
        rpy="0 0 0" />
      <mass
        value="0.000911356888660495" />
      <inertia
        ixx="2.8541034821061E-08"
        ixy="-2.22197427857281E-10"
        ixz="7.87903579180728E-11"
        iyy="4.99346433608489E-08"
        iyz="-4.13194761846516E-11"
        izz="7.78569805080497E-08" />
    </inertial>
    <visual>
      <origin
        xyz="0 0 0"
        rpy="0 0 0" />
      <geometry>
        <mesh
          filename="package://smr100e_description/meshes/imu_link.STL" />
      </geometry>
      <material
        name="">
        <color
          rgba="0.792156862745098 0.819607843137255 0.933333333333333 1" />
      </material>
    </visual>
    <collision>
      <origin
        xyz="0 0 0"
        rpy="0 0 0" />
      <geometry>
        <mesh
          filename="package://smr100e_description/meshes/imu_link.STL" />
      </geometry>
    </collision>
  </link>
  <joint
    name="imu_joint"
    type="fixed">
    <origin
      xyz="0.06095 0.005 0.26398"
      rpy="0 0 -1.5708" />
    <parent
      link="base_link" />
    <child
      link="imu_link" />
    <axis
      xyz="0 0 0" />
  </joint>
</robot>